The files belonging to this database system will be owned by user "postgres".
This user must also own the server process.

The database cluster will be initialized with locale "en_US.utf8".
The default database encoding has accordingly been set to "UTF8".
The default text search configuration will be set to "english".

Data page checksums are disabled.

fixing permissions on existing directory /var/lib/postgresql/data ... ok
creating subdirectories ... ok
selecting dynamic shared memory implementation ... posix
selecting default max_connections ... 100
selecting default shared_buffers ... 128MB
selecting default time zone ... Etc/UTC
creating configuration files ... ok
running bootstrap script ... ok
performing post-bootstrap initialization ... ok
syncing data to disk ... ok


Success. You can now start the database server using:

    pg_ctl -D /var/lib/postgresql/data -l logfile start

initdb: warning: enabling "trust" authentication for local connections
initdb: hint: You can change this by editing pg_hba.conf or using the option -A, or --auth-local and --auth-host, the next time you run initdb.
waiting for server to start....2025-01-28 14:40:25.376 UTC [48] LOG:  starting PostgreSQL 16.6 (Debian 16.6-1.pgdg120+1) on x86_64-pc-linux-gnu, compiled by gcc (Debian 12.2.0-14) 12.2.0, 64-bit
2025-01-28 14:40:25.377 UTC [48] LOG:  listening on Unix socket "/var/run/postgresql/.s.PGSQL.5432"
2025-01-28 14:40:25.380 UTC [51] LOG:  database system was shut down at 2025-01-28 14:40:25 UTC
2025-01-28 14:40:25.383 UTC [48] LOG:  database system is ready to accept connections
 done
server started
CREATE DATABASE


/usr/local/bin/docker-entrypoint.sh: ignoring /docker-entrypoint-initdb.d/*

waiting for server to shut down....2025-01-28 14:40:25.545 UTC [48] LOG:  received fast shutdown request
2025-01-28 14:40:25.546 UTC [48] LOG:  aborting any active transactions
2025-01-28 14:40:25.548 UTC [48] LOG:  background worker "logical replication launcher" (PID 54) exited with exit code 1
2025-01-28 14:40:25.548 UTC [49] LOG:  shutting down
2025-01-28 14:40:25.549 UTC [49] LOG:  checkpoint starting: shutdown immediate
2025-01-28 14:40:25.589 UTC [49] LOG:  checkpoint complete: wrote 922 buffers (5.6%); 0 WAL file(s) added, 0 removed, 0 recycled; write=0.013 s, sync=0.025 s, total=0.042 s; sync files=301, longest=0.005 s, average=0.001 s; distance=4255 kB, estimate=4255 kB; lsn=0/19120F8, redo lsn=0/19120F8
2025-01-28 14:40:25.595 UTC [48] LOG:  database system is shut down
 done
server stopped

PostgreSQL init process complete; ready for start up.

2025-01-28 14:40:25.659 UTC [1] LOG:  starting PostgreSQL 16.6 (Debian 16.6-1.pgdg120+1) on x86_64-pc-linux-gnu, compiled by gcc (Debian 12.2.0-14) 12.2.0, 64-bit
2025-01-28 14:40:25.659 UTC [1] LOG:  listening on IPv4 address "0.0.0.0", port 5432
2025-01-28 14:40:25.659 UTC [1] LOG:  listening on IPv6 address "::", port 5432
2025-01-28 14:40:25.661 UTC [1] LOG:  listening on Unix socket "/var/run/postgresql/.s.PGSQL.5432"
2025-01-28 14:40:25.663 UTC [64] LOG:  database system was shut down at 2025-01-28 14:40:25 UTC
2025-01-28 14:40:25.666 UTC [1] LOG:  database system is ready to accept connections
2025-01-28 14:44:12.788 UTC [127] ERROR:  relation "auth_user" does not exist at character 280
2025-01-28 14:44:12.788 UTC [127] STATEMENT:  SELECT "auth_user"."id", "auth_user"."password", "auth_user"."last_login", "auth_user"."is_superuser", "auth_user"."username", "auth_user"."first_name", "auth_user"."last_name", "auth_user"."email", "auth_user"."is_staff", "auth_user"."is_active", "auth_user"."date_joined" FROM "auth_user" WHERE "auth_user"."username" = 'toto' LIMIT 21
2025-01-28 14:44:12.798 UTC [127] ERROR:  relation "django_admin_log" does not exist at character 638
2025-01-28 14:44:12.798 UTC [127] STATEMENT:  SELECT "django_admin_log"."id", "django_admin_log"."action_time", "django_admin_log"."user_id", "django_admin_log"."content_type_id", "django_admin_log"."object_id", "django_admin_log"."object_repr", "django_admin_log"."action_flag", "django_admin_log"."change_message", "auth_user"."id", "auth_user"."password", "auth_user"."last_login", "auth_user"."is_superuser", "auth_user"."username", "auth_user"."first_name", "auth_user"."last_name", "auth_user"."email", "auth_user"."is_staff", "auth_user"."is_active", "auth_user"."date_joined", "django_content_type"."id", "django_content_type"."app_label", "django_content_type"."model" FROM "django_admin_log" INNER JOIN "auth_user" ON ("django_admin_log"."user_id" = "auth_user"."id") LEFT OUTER JOIN "django_content_type" ON ("django_admin_log"."content_type_id" = "django_content_type"."id") ORDER BY "django_admin_log"."action_time" DESC LIMIT 21
2025-01-28 14:44:12.799 UTC [127] ERROR:  relation "django_admin_log" does not exist at character 638
2025-01-28 14:44:12.799 UTC [127] STATEMENT:  SELECT "django_admin_log"."id", "django_admin_log"."action_time", "django_admin_log"."user_id", "django_admin_log"."content_type_id", "django_admin_log"."object_id", "django_admin_log"."object_repr", "django_admin_log"."action_flag", "django_admin_log"."change_message", "auth_user"."id", "auth_user"."password", "auth_user"."last_login", "auth_user"."is_superuser", "auth_user"."username", "auth_user"."first_name", "auth_user"."last_name", "auth_user"."email", "auth_user"."is_staff", "auth_user"."is_active", "auth_user"."date_joined", "django_content_type"."id", "django_content_type"."app_label", "django_content_type"."model" FROM "django_admin_log" INNER JOIN "auth_user" ON ("django_admin_log"."user_id" = "auth_user"."id") LEFT OUTER JOIN "django_content_type" ON ("django_admin_log"."content_type_id" = "django_content_type"."id") ORDER BY "django_admin_log"."action_time" DESC LIMIT 21
2025-01-28 14:44:12.800 UTC [127] ERROR:  relation "django_admin_log" does not exist at character 638
2025-01-28 14:44:12.800 UTC [127] STATEMENT:  SELECT "django_admin_log"."id", "django_admin_log"."action_time", "django_admin_log"."user_id", "django_admin_log"."content_type_id", "django_admin_log"."object_id", "django_admin_log"."object_repr", "django_admin_log"."action_flag", "django_admin_log"."change_message", "auth_user"."id", "auth_user"."password", "auth_user"."last_login", "auth_user"."is_superuser", "auth_user"."username", "auth_user"."first_name", "auth_user"."last_name", "auth_user"."email", "auth_user"."is_staff", "auth_user"."is_active", "auth_user"."date_joined", "django_content_type"."id", "django_content_type"."app_label", "django_content_type"."model" FROM "django_admin_log" INNER JOIN "auth_user" ON ("django_admin_log"."user_id" = "auth_user"."id") LEFT OUTER JOIN "django_content_type" ON ("django_admin_log"."content_type_id" = "django_content_type"."id") ORDER BY "django_admin_log"."action_time" DESC LIMIT 21
2025-01-28 14:44:12.801 UTC [127] ERROR:  relation "auth_user" does not exist at character 280
2025-01-28 14:44:12.801 UTC [127] STATEMENT:  SELECT "auth_user"."id", "auth_user"."password", "auth_user"."last_login", "auth_user"."is_superuser", "auth_user"."username", "auth_user"."first_name", "auth_user"."last_name", "auth_user"."email", "auth_user"."is_staff", "auth_user"."is_active", "auth_user"."date_joined" FROM "auth_user" LIMIT 21
2025-01-28 14:44:12.802 UTC [127] ERROR:  relation "auth_user" does not exist at character 280
2025-01-28 14:44:12.802 UTC [127] STATEMENT:  SELECT "auth_user"."id", "auth_user"."password", "auth_user"."last_login", "auth_user"."is_superuser", "auth_user"."username", "auth_user"."first_name", "auth_user"."last_name", "auth_user"."email", "auth_user"."is_staff", "auth_user"."is_active", "auth_user"."date_joined" FROM "auth_user" WHERE "auth_user"."username" = 'toto' LIMIT 21
2025-01-28 14:44:12.802 UTC [127] ERROR:  relation "auth_user" does not exist at character 280
2025-01-28 14:44:12.802 UTC [127] STATEMENT:  SELECT "auth_user"."id", "auth_user"."password", "auth_user"."last_login", "auth_user"."is_superuser", "auth_user"."username", "auth_user"."first_name", "auth_user"."last_name", "auth_user"."email", "auth_user"."is_staff", "auth_user"."is_active", "auth_user"."date_joined" FROM "auth_user" WHERE "auth_user"."username" = 'toto' LIMIT 21
2025-01-28 14:44:12.803 UTC [127] ERROR:  relation "auth_user" does not exist at character 280
2025-01-28 14:44:12.803 UTC [127] STATEMENT:  SELECT "auth_user"."id", "auth_user"."password", "auth_user"."last_login", "auth_user"."is_superuser", "auth_user"."username", "auth_user"."first_name", "auth_user"."last_name", "auth_user"."email", "auth_user"."is_staff", "auth_user"."is_active", "auth_user"."date_joined" FROM "auth_user" WHERE "auth_user"."username" = 'toto' LIMIT 21
2025-01-28 14:44:12.804 UTC [127] ERROR:  relation "auth_user" does not exist at character 280
2025-01-28 14:44:12.804 UTC [127] STATEMENT:  SELECT "auth_user"."id", "auth_user"."password", "auth_user"."last_login", "auth_user"."is_superuser", "auth_user"."username", "auth_user"."first_name", "auth_user"."last_name", "auth_user"."email", "auth_user"."is_staff", "auth_user"."is_active", "auth_user"."date_joined" FROM "auth_user" WHERE "auth_user"."username" = 'toto' LIMIT 21
2025-01-28 14:45:25.768 UTC [62] LOG:  checkpoint starting: time
2025-01-28 14:45:29.993 UTC [62] LOG:  checkpoint complete: wrote 45 buffers (0.3%); 0 WAL file(s) added, 0 removed, 0 recycled; write=4.214 s, sync=0.008 s, total=4.231 s; sync files=12, longest=0.007 s, average=0.001 s; distance=261 kB, estimate=261 kB; lsn=0/1953550, redo lsn=0/1953518
2025-01-28 14:47:13.206 UTC [1] LOG:  received fast shutdown request
2025-01-28 14:47:13.207 UTC [1] LOG:  aborting any active transactions
2025-01-28 14:47:13.207 UTC [83] FATAL:  terminating connection due to administrator command
2025-01-28 14:47:13.208 UTC [1] LOG:  background worker "logical replication launcher" (PID 67) exited with exit code 1
2025-01-28 14:47:13.208 UTC [62] LOG:  shutting down
2025-01-28 14:47:13.209 UTC [62] LOG:  checkpoint starting: shutdown immediate
2025-01-28 14:47:13.211 UTC [62] LOG:  checkpoint complete: wrote 0 buffers (0.0%); 0 WAL file(s) added, 0 removed, 0 recycled; write=0.001 s, sync=0.001 s, total=0.003 s; sync files=0, longest=0.000 s, average=0.000 s; distance=0 kB, estimate=234 kB; lsn=0/1953600, redo lsn=0/1953600
2025-01-28 14:47:13.213 UTC [1] LOG:  database system is shut down
